INFO:root:Бот стартовал
INFO:apscheduler.scheduler:Scheduler started
INFO:root:Бот стартовал
INFO:apscheduler.scheduler:Scheduler started
INFO:root:Бот стартовал
INFO:apscheduler.scheduler:Scheduler started
ERROR:telegram.ext.updater:Error while getting Updates: Conflict: terminated by other getUpdates request; make sure that only one bot instance is running
ERROR:telegram.ext.dispatcher:No error handlers are registered, logging exception.
Traceback (most recent call last):
  File "C:\Users\Кирилл\AppData\Local\Programs\Python\Python39\lib\site-packages\telegram\ext\updater.py", line 646, in _network_loop_retry
    if not action_cb():
  File "C:\Users\Кирилл\AppData\Local\Programs\Python\Python39\lib\site-packages\telegram\ext\updater.py", line 597, in polling_action_cb
    updates = self.bot.get_updates(
  File "C:\Users\Кирилл\AppData\Local\Programs\Python\Python39\lib\site-packages\telegram\ext\extbot.py", line 222, in get_updates
    updates = super().get_updates(
  File "C:\Users\Кирилл\AppData\Local\Programs\Python\Python39\lib\site-packages\telegram\bot.py", line 130, in decorator
    result = func(*args, **kwargs)
  File "C:\Users\Кирилл\AppData\Local\Programs\Python\Python39\lib\site-packages\telegram\bot.py", line 2861, in get_updates
    self._post(
  File "C:\Users\Кирилл\AppData\Local\Programs\Python\Python39\lib\site-packages\telegram\bot.py", line 295, in _post
    return self.request.post(
  File "C:\Users\Кирилл\AppData\Local\Programs\Python\Python39\lib\site-packages\telegram\utils\request.py", line 356, in post
    result = self._request_wrapper(
  File "C:\Users\Кирилл\AppData\Local\Programs\Python\Python39\lib\site-packages\telegram\utils\request.py", line 283, in _request_wrapper
    raise Conflict(message)
telegram.error.Conflict: Conflict: terminated by other getUpdates request; make sure that only one bot instance is running
ERROR:telegram.ext.updater:Error while getting Updates: Conflict: terminated by other getUpdates request; make sure that only one bot instance is running
ERROR:telegram.ext.dispatcher:No error handlers are registered, logging exception.
Traceback (most recent call last):
  File "C:\Users\Кирилл\AppData\Local\Programs\Python\Python39\lib\site-packages\telegram\ext\updater.py", line 646, in _network_loop_retry
    if not action_cb():
  File "C:\Users\Кирилл\AppData\Local\Programs\Python\Python39\lib\site-packages\telegram\ext\updater.py", line 597, in polling_action_cb
    updates = self.bot.get_updates(
  File "C:\Users\Кирилл\AppData\Local\Programs\Python\Python39\lib\site-packages\telegram\ext\extbot.py", line 222, in get_updates
    updates = super().get_updates(
  File "C:\Users\Кирилл\AppData\Local\Programs\Python\Python39\lib\site-packages\telegram\bot.py", line 130, in decorator
    result = func(*args, **kwargs)
  File "C:\Users\Кирилл\AppData\Local\Programs\Python\Python39\lib\site-packages\telegram\bot.py", line 2861, in get_updates
    self._post(
  File "C:\Users\Кирилл\AppData\Local\Programs\Python\Python39\lib\site-packages\telegram\bot.py", line 295, in _post
    return self.request.post(
  File "C:\Users\Кирилл\AppData\Local\Programs\Python\Python39\lib\site-packages\telegram\utils\request.py", line 356, in post
    result = self._request_wrapper(
  File "C:\Users\Кирилл\AppData\Local\Programs\Python\Python39\lib\site-packages\telegram\utils\request.py", line 283, in _request_wrapper
    raise Conflict(message)
telegram.error.Conflict: Conflict: terminated by other getUpdates request; make sure that only one bot instance is running
ERROR:telegram.ext.updater:Error while getting Updates: Conflict: terminated by other getUpdates request; make sure that only one bot instance is running
ERROR:telegram.ext.dispatcher:No error handlers are registered, logging exception.
Traceback (most recent call last):
  File "C:\Users\Кирилл\AppData\Local\Programs\Python\Python39\lib\site-packages\telegram\ext\updater.py", line 646, in _network_loop_retry
    if not action_cb():
  File "C:\Users\Кирилл\AppData\Local\Programs\Python\Python39\lib\site-packages\telegram\ext\updater.py", line 597, in polling_action_cb
    updates = self.bot.get_updates(
  File "C:\Users\Кирилл\AppData\Local\Programs\Python\Python39\lib\site-packages\telegram\ext\extbot.py", line 222, in get_updates
    updates = super().get_updates(
  File "C:\Users\Кирилл\AppData\Local\Programs\Python\Python39\lib\site-packages\telegram\bot.py", line 130, in decorator
    result = func(*args, **kwargs)
  File "C:\Users\Кирилл\AppData\Local\Programs\Python\Python39\lib\site-packages\telegram\bot.py", line 2861, in get_updates
    self._post(
  File "C:\Users\Кирилл\AppData\Local\Programs\Python\Python39\lib\site-packages\telegram\bot.py", line 295, in _post
    return self.request.post(
  File "C:\Users\Кирилл\AppData\Local\Programs\Python\Python39\lib\site-packages\telegram\utils\request.py", line 356, in post
    result = self._request_wrapper(
  File "C:\Users\Кирилл\AppData\Local\Programs\Python\Python39\lib\site-packages\telegram\utils\request.py", line 283, in _request_wrapper
    raise Conflict(message)
telegram.error.Conflict: Conflict: terminated by other getUpdates request; make sure that only one bot instance is running
ERROR:telegram.ext.updater:Error while getting Updates: Conflict: terminated by other getUpdates request; make sure that only one bot instance is running
ERROR:telegram.ext.dispatcher:No error handlers are registered, logging exception.
Traceback (most recent call last):
  File "C:\Users\Кирилл\AppData\Local\Programs\Python\Python39\lib\site-packages\telegram\ext\updater.py", line 646, in _network_loop_retry
    if not action_cb():
  File "C:\Users\Кирилл\AppData\Local\Programs\Python\Python39\lib\site-packages\telegram\ext\updater.py", line 597, in polling_action_cb
    updates = self.bot.get_updates(
  File "C:\Users\Кирилл\AppData\Local\Programs\Python\Python39\lib\site-packages\telegram\ext\extbot.py", line 222, in get_updates
    updates = super().get_updates(
  File "C:\Users\Кирилл\AppData\Local\Programs\Python\Python39\lib\site-packages\telegram\bot.py", line 130, in decorator
    result = func(*args, **kwargs)
  File "C:\Users\Кирилл\AppData\Local\Programs\Python\Python39\lib\site-packages\telegram\bot.py", line 2861, in get_updates
    self._post(
  File "C:\Users\Кирилл\AppData\Local\Programs\Python\Python39\lib\site-packages\telegram\bot.py", line 295, in _post
    return self.request.post(
  File "C:\Users\Кирилл\AppData\Local\Programs\Python\Python39\lib\site-packages\telegram\utils\request.py", line 356, in post
    result = self._request_wrapper(
  File "C:\Users\Кирилл\AppData\Local\Programs\Python\Python39\lib\site-packages\telegram\utils\request.py", line 283, in _request_wrapper
    raise Conflict(message)
telegram.error.Conflict: Conflict: terminated by other getUpdates request; make sure that only one bot instance is running
ERROR:telegram.ext.updater:Error while getting Updates: Conflict: terminated by other getUpdates request; make sure that only one bot instance is running
ERROR:telegram.ext.dispatcher:No error handlers are registered, logging exception.
Traceback (most recent call last):
  File "C:\Users\Кирилл\AppData\Local\Programs\Python\Python39\lib\site-packages\telegram\ext\updater.py", line 646, in _network_loop_retry
    if not action_cb():
  File "C:\Users\Кирилл\AppData\Local\Programs\Python\Python39\lib\site-packages\telegram\ext\updater.py", line 597, in polling_action_cb
    updates = self.bot.get_updates(
  File "C:\Users\Кирилл\AppData\Local\Programs\Python\Python39\lib\site-packages\telegram\ext\extbot.py", line 222, in get_updates
    updates = super().get_updates(
  File "C:\Users\Кирилл\AppData\Local\Programs\Python\Python39\lib\site-packages\telegram\bot.py", line 130, in decorator
    result = func(*args, **kwargs)
  File "C:\Users\Кирилл\AppData\Local\Programs\Python\Python39\lib\site-packages\telegram\bot.py", line 2861, in get_updates
    self._post(
  File "C:\Users\Кирилл\AppData\Local\Programs\Python\Python39\lib\site-packages\telegram\bot.py", line 295, in _post
    return self.request.post(
  File "C:\Users\Кирилл\AppData\Local\Programs\Python\Python39\lib\site-packages\telegram\utils\request.py", line 356, in post
    result = self._request_wrapper(
  File "C:\Users\Кирилл\AppData\Local\Programs\Python\Python39\lib\site-packages\telegram\utils\request.py", line 283, in _request_wrapper
    raise Conflict(message)
telegram.error.Conflict: Conflict: terminated by other getUpdates request; make sure that only one bot instance is running
ERROR:telegram.ext.updater:Error while getting Updates: Conflict: terminated by other getUpdates request; make sure that only one bot instance is running
ERROR:telegram.ext.dispatcher:No error handlers are registered, logging exception.
Traceback (most recent call last):
  File "C:\Users\Кирилл\AppData\Local\Programs\Python\Python39\lib\site-packages\telegram\ext\updater.py", line 646, in _network_loop_retry
    if not action_cb():
  File "C:\Users\Кирилл\AppData\Local\Programs\Python\Python39\lib\site-packages\telegram\ext\updater.py", line 597, in polling_action_cb
    updates = self.bot.get_updates(
  File "C:\Users\Кирилл\AppData\Local\Programs\Python\Python39\lib\site-packages\telegram\ext\extbot.py", line 222, in get_updates
    updates = super().get_updates(
  File "C:\Users\Кирилл\AppData\Local\Programs\Python\Python39\lib\site-packages\telegram\bot.py", line 130, in decorator
    result = func(*args, **kwargs)
  File "C:\Users\Кирилл\AppData\Local\Programs\Python\Python39\lib\site-packages\telegram\bot.py", line 2861, in get_updates
    self._post(
  File "C:\Users\Кирилл\AppData\Local\Programs\Python\Python39\lib\site-packages\telegram\bot.py", line 295, in _post
    return self.request.post(
  File "C:\Users\Кирилл\AppData\Local\Programs\Python\Python39\lib\site-packages\telegram\utils\request.py", line 356, in post
    result = self._request_wrapper(
  File "C:\Users\Кирилл\AppData\Local\Programs\Python\Python39\lib\site-packages\telegram\utils\request.py", line 283, in _request_wrapper
    raise Conflict(message)
telegram.error.Conflict: Conflict: terminated by other getUpdates request; make sure that only one bot instance is running
ERROR:telegram.ext.updater:Error while getting Updates: Conflict: terminated by other getUpdates request; make sure that only one bot instance is running
ERROR:telegram.ext.dispatcher:No error handlers are registered, logging exception.
Traceback (most recent call last):
  File "C:\Users\Кирилл\AppData\Local\Programs\Python\Python39\lib\site-packages\telegram\ext\updater.py", line 646, in _network_loop_retry
    if not action_cb():
  File "C:\Users\Кирилл\AppData\Local\Programs\Python\Python39\lib\site-packages\telegram\ext\updater.py", line 597, in polling_action_cb
    updates = self.bot.get_updates(
  File "C:\Users\Кирилл\AppData\Local\Programs\Python\Python39\lib\site-packages\telegram\ext\extbot.py", line 222, in get_updates
    updates = super().get_updates(
  File "C:\Users\Кирилл\AppData\Local\Programs\Python\Python39\lib\site-packages\telegram\bot.py", line 130, in decorator
    result = func(*args, **kwargs)
  File "C:\Users\Кирилл\AppData\Local\Programs\Python\Python39\lib\site-packages\telegram\bot.py", line 2861, in get_updates
    self._post(
  File "C:\Users\Кирилл\AppData\Local\Programs\Python\Python39\lib\site-packages\telegram\bot.py", line 295, in _post
    return self.request.post(
  File "C:\Users\Кирилл\AppData\Local\Programs\Python\Python39\lib\site-packages\telegram\utils\request.py", line 356, in post
    result = self._request_wrapper(
  File "C:\Users\Кирилл\AppData\Local\Programs\Python\Python39\lib\site-packages\telegram\utils\request.py", line 283, in _request_wrapper
    raise Conflict(message)
telegram.error.Conflict: Conflict: terminated by other getUpdates request; make sure that only one bot instance is running
ERROR:telegram.ext.updater:Error while getting Updates: Conflict: terminated by other getUpdates request; make sure that only one bot instance is running
ERROR:telegram.ext.dispatcher:No error handlers are registered, logging exception.
Traceback (most recent call last):
  File "C:\Users\Кирилл\AppData\Local\Programs\Python\Python39\lib\site-packages\telegram\ext\updater.py", line 646, in _network_loop_retry
    if not action_cb():
  File "C:\Users\Кирилл\AppData\Local\Programs\Python\Python39\lib\site-packages\telegram\ext\updater.py", line 597, in polling_action_cb
    updates = self.bot.get_updates(
  File "C:\Users\Кирилл\AppData\Local\Programs\Python\Python39\lib\site-packages\telegram\ext\extbot.py", line 222, in get_updates
    updates = super().get_updates(
  File "C:\Users\Кирилл\AppData\Local\Programs\Python\Python39\lib\site-packages\telegram\bot.py", line 130, in decorator
    result = func(*args, **kwargs)
  File "C:\Users\Кирилл\AppData\Local\Programs\Python\Python39\lib\site-packages\telegram\bot.py", line 2861, in get_updates
    self._post(
  File "C:\Users\Кирилл\AppData\Local\Programs\Python\Python39\lib\site-packages\telegram\bot.py", line 295, in _post
    return self.request.post(
  File "C:\Users\Кирилл\AppData\Local\Programs\Python\Python39\lib\site-packages\telegram\utils\request.py", line 356, in post
    result = self._request_wrapper(
  File "C:\Users\Кирилл\AppData\Local\Programs\Python\Python39\lib\site-packages\telegram\utils\request.py", line 283, in _request_wrapper
    raise Conflict(message)
telegram.error.Conflict: Conflict: terminated by other getUpdates request; make sure that only one bot instance is running
ERROR:telegram.ext.updater:Error while getting Updates: Conflict: terminated by other getUpdates request; make sure that only one bot instance is running
ERROR:telegram.ext.dispatcher:No error handlers are registered, logging exception.
Traceback (most recent call last):
  File "C:\Users\Кирилл\AppData\Local\Programs\Python\Python39\lib\site-packages\telegram\ext\updater.py", line 646, in _network_loop_retry
    if not action_cb():
  File "C:\Users\Кирилл\AppData\Local\Programs\Python\Python39\lib\site-packages\telegram\ext\updater.py", line 597, in polling_action_cb
    updates = self.bot.get_updates(
  File "C:\Users\Кирилл\AppData\Local\Programs\Python\Python39\lib\site-packages\telegram\ext\extbot.py", line 222, in get_updates
    updates = super().get_updates(
  File "C:\Users\Кирилл\AppData\Local\Programs\Python\Python39\lib\site-packages\telegram\bot.py", line 130, in decorator
    result = func(*args, **kwargs)
  File "C:\Users\Кирилл\AppData\Local\Programs\Python\Python39\lib\site-packages\telegram\bot.py", line 2861, in get_updates
    self._post(
  File "C:\Users\Кирилл\AppData\Local\Programs\Python\Python39\lib\site-packages\telegram\bot.py", line 295, in _post
    return self.request.post(
  File "C:\Users\Кирилл\AppData\Local\Programs\Python\Python39\lib\site-packages\telegram\utils\request.py", line 356, in post
    result = self._request_wrapper(
  File "C:\Users\Кирилл\AppData\Local\Programs\Python\Python39\lib\site-packages\telegram\utils\request.py", line 283, in _request_wrapper
    raise Conflict(message)
telegram.error.Conflict: Conflict: terminated by other getUpdates request; make sure that only one bot instance is running
ERROR:telegram.ext.updater:Error while getting Updates: Conflict: terminated by other getUpdates request; make sure that only one bot instance is running
ERROR:telegram.ext.dispatcher:No error handlers are registered, logging exception.
Traceback (most recent call last):
  File "C:\Users\Кирилл\AppData\Local\Programs\Python\Python39\lib\site-packages\telegram\ext\updater.py", line 646, in _network_loop_retry
    if not action_cb():
  File "C:\Users\Кирилл\AppData\Local\Programs\Python\Python39\lib\site-packages\telegram\ext\updater.py", line 597, in polling_action_cb
    updates = self.bot.get_updates(
  File "C:\Users\Кирилл\AppData\Local\Programs\Python\Python39\lib\site-packages\telegram\ext\extbot.py", line 222, in get_updates
    updates = super().get_updates(
  File "C:\Users\Кирилл\AppData\Local\Programs\Python\Python39\lib\site-packages\telegram\bot.py", line 130, in decorator
    result = func(*args, **kwargs)
  File "C:\Users\Кирилл\AppData\Local\Programs\Python\Python39\lib\site-packages\telegram\bot.py", line 2861, in get_updates
    self._post(
  File "C:\Users\Кирилл\AppData\Local\Programs\Python\Python39\lib\site-packages\telegram\bot.py", line 295, in _post
    return self.request.post(
  File "C:\Users\Кирилл\AppData\Local\Programs\Python\Python39\lib\site-packages\telegram\utils\request.py", line 356, in post
    result = self._request_wrapper(
  File "C:\Users\Кирилл\AppData\Local\Programs\Python\Python39\lib\site-packages\telegram\utils\request.py", line 283, in _request_wrapper
    raise Conflict(message)
telegram.error.Conflict: Conflict: terminated by other getUpdates request; make sure that only one bot instance is running
ERROR:telegram.ext.updater:Error while getting Updates: Conflict: terminated by other getUpdates request; make sure that only one bot instance is running
ERROR:telegram.ext.dispatcher:No error handlers are registered, logging exception.
Traceback (most recent call last):
  File "C:\Users\Кирилл\AppData\Local\Programs\Python\Python39\lib\site-packages\telegram\ext\updater.py", line 646, in _network_loop_retry
    if not action_cb():
  File "C:\Users\Кирилл\AppData\Local\Programs\Python\Python39\lib\site-packages\telegram\ext\updater.py", line 597, in polling_action_cb
    updates = self.bot.get_updates(
  File "C:\Users\Кирилл\AppData\Local\Programs\Python\Python39\lib\site-packages\telegram\ext\extbot.py", line 222, in get_updates
    updates = super().get_updates(
  File "C:\Users\Кирилл\AppData\Local\Programs\Python\Python39\lib\site-packages\telegram\bot.py", line 130, in decorator
    result = func(*args, **kwargs)
  File "C:\Users\Кирилл\AppData\Local\Programs\Python\Python39\lib\site-packages\telegram\bot.py", line 2861, in get_updates
    self._post(
  File "C:\Users\Кирилл\AppData\Local\Programs\Python\Python39\lib\site-packages\telegram\bot.py", line 295, in _post
    return self.request.post(
  File "C:\Users\Кирилл\AppData\Local\Programs\Python\Python39\lib\site-packages\telegram\utils\request.py", line 356, in post
    result = self._request_wrapper(
  File "C:\Users\Кирилл\AppData\Local\Programs\Python\Python39\lib\site-packages\telegram\utils\request.py", line 283, in _request_wrapper
    raise Conflict(message)
telegram.error.Conflict: Conflict: terminated by other getUpdates request; make sure that only one bot instance is running
ERROR:telegram.ext.updater:Error while getting Updates: Conflict: terminated by other getUpdates request; make sure that only one bot instance is running
ERROR:telegram.ext.dispatcher:No error handlers are registered, logging exception.
Traceback (most recent call last):
  File "C:\Users\Кирилл\AppData\Local\Programs\Python\Python39\lib\site-packages\telegram\ext\updater.py", line 646, in _network_loop_retry
    if not action_cb():
  File "C:\Users\Кирилл\AppData\Local\Programs\Python\Python39\lib\site-packages\telegram\ext\updater.py", line 597, in polling_action_cb
    updates = self.bot.get_updates(
  File "C:\Users\Кирилл\AppData\Local\Programs\Python\Python39\lib\site-packages\telegram\ext\extbot.py", line 222, in get_updates
    updates = super().get_updates(
  File "C:\Users\Кирилл\AppData\Local\Programs\Python\Python39\lib\site-packages\telegram\bot.py", line 130, in decorator
    result = func(*args, **kwargs)
  File "C:\Users\Кирилл\AppData\Local\Programs\Python\Python39\lib\site-packages\telegram\bot.py", line 2861, in get_updates
    self._post(
  File "C:\Users\Кирилл\AppData\Local\Programs\Python\Python39\lib\site-packages\telegram\bot.py", line 295, in _post
    return self.request.post(
  File "C:\Users\Кирилл\AppData\Local\Programs\Python\Python39\lib\site-packages\telegram\utils\request.py", line 356, in post
    result = self._request_wrapper(
  File "C:\Users\Кирилл\AppData\Local\Programs\Python\Python39\lib\site-packages\telegram\utils\request.py", line 283, in _request_wrapper
    raise Conflict(message)
telegram.error.Conflict: Conflict: terminated by other getUpdates request; make sure that only one bot instance is running
ERROR:telegram.ext.updater:Error while getting Updates: Conflict: terminated by other getUpdates request; make sure that only one bot instance is running
ERROR:telegram.ext.dispatcher:No error handlers are registered, logging exception.
Traceback (most recent call last):
  File "C:\Users\Кирилл\AppData\Local\Programs\Python\Python39\lib\site-packages\telegram\ext\updater.py", line 646, in _network_loop_retry
    if not action_cb():
  File "C:\Users\Кирилл\AppData\Local\Programs\Python\Python39\lib\site-packages\telegram\ext\updater.py", line 597, in polling_action_cb
    updates = self.bot.get_updates(
  File "C:\Users\Кирилл\AppData\Local\Programs\Python\Python39\lib\site-packages\telegram\ext\extbot.py", line 222, in get_updates
    updates = super().get_updates(
  File "C:\Users\Кирилл\AppData\Local\Programs\Python\Python39\lib\site-packages\telegram\bot.py", line 130, in decorator
    result = func(*args, **kwargs)
  File "C:\Users\Кирилл\AppData\Local\Programs\Python\Python39\lib\site-packages\telegram\bot.py", line 2861, in get_updates
    self._post(
  File "C:\Users\Кирилл\AppData\Local\Programs\Python\Python39\lib\site-packages\telegram\bot.py", line 295, in _post
    return self.request.post(
  File "C:\Users\Кирилл\AppData\Local\Programs\Python\Python39\lib\site-packages\telegram\utils\request.py", line 356, in post
    result = self._request_wrapper(
  File "C:\Users\Кирилл\AppData\Local\Programs\Python\Python39\lib\site-packages\telegram\utils\request.py", line 283, in _request_wrapper
    raise Conflict(message)
telegram.error.Conflict: Conflict: terminated by other getUpdates request; make sure that only one bot instance is running
ERROR:telegram.ext.updater:Error while getting Updates: Conflict: terminated by other getUpdates request; make sure that only one bot instance is running
ERROR:telegram.ext.dispatcher:No error handlers are registered, logging exception.
Traceback (most recent call last):
  File "C:\Users\Кирилл\AppData\Local\Programs\Python\Python39\lib\site-packages\telegram\ext\updater.py", line 646, in _network_loop_retry
    if not action_cb():
  File "C:\Users\Кирилл\AppData\Local\Programs\Python\Python39\lib\site-packages\telegram\ext\updater.py", line 597, in polling_action_cb
    updates = self.bot.get_updates(
  File "C:\Users\Кирилл\AppData\Local\Programs\Python\Python39\lib\site-packages\telegram\ext\extbot.py", line 222, in get_updates
    updates = super().get_updates(
  File "C:\Users\Кирилл\AppData\Local\Programs\Python\Python39\lib\site-packages\telegram\bot.py", line 130, in decorator
    result = func(*args, **kwargs)
  File "C:\Users\Кирилл\AppData\Local\Programs\Python\Python39\lib\site-packages\telegram\bot.py", line 2861, in get_updates
    self._post(
  File "C:\Users\Кирилл\AppData\Local\Programs\Python\Python39\lib\site-packages\telegram\bot.py", line 295, in _post
    return self.request.post(
  File "C:\Users\Кирилл\AppData\Local\Programs\Python\Python39\lib\site-packages\telegram\utils\request.py", line 356, in post
    result = self._request_wrapper(
  File "C:\Users\Кирилл\AppData\Local\Programs\Python\Python39\lib\site-packages\telegram\utils\request.py", line 283, in _request_wrapper
    raise Conflict(message)
telegram.error.Conflict: Conflict: terminated by other getUpdates request; make sure that only one bot instance is running
INFO:root:Бот стартовал
INFO:apscheduler.scheduler:Scheduler started
ERROR:telegram.ext.updater:Error while getting Updates: Conflict: terminated by other getUpdates request; make sure that only one bot instance is running
ERROR:telegram.ext.dispatcher:No error handlers are registered, logging exception.
Traceback (most recent call last):
  File "C:\Users\Кирилл\AppData\Local\Programs\Python\Python39\lib\site-packages\telegram\ext\updater.py", line 646, in _network_loop_retry
    if not action_cb():
  File "C:\Users\Кирилл\AppData\Local\Programs\Python\Python39\lib\site-packages\telegram\ext\updater.py", line 597, in polling_action_cb
    updates = self.bot.get_updates(
  File "C:\Users\Кирилл\AppData\Local\Programs\Python\Python39\lib\site-packages\telegram\ext\extbot.py", line 222, in get_updates
    updates = super().get_updates(
  File "C:\Users\Кирилл\AppData\Local\Programs\Python\Python39\lib\site-packages\telegram\bot.py", line 130, in decorator
    result = func(*args, **kwargs)
  File "C:\Users\Кирилл\AppData\Local\Programs\Python\Python39\lib\site-packages\telegram\bot.py", line 2861, in get_updates
    self._post(
  File "C:\Users\Кирилл\AppData\Local\Programs\Python\Python39\lib\site-packages\telegram\bot.py", line 295, in _post
    return self.request.post(
  File "C:\Users\Кирилл\AppData\Local\Programs\Python\Python39\lib\site-packages\telegram\utils\request.py", line 356, in post
    result = self._request_wrapper(
  File "C:\Users\Кирилл\AppData\Local\Programs\Python\Python39\lib\site-packages\telegram\utils\request.py", line 283, in _request_wrapper
    raise Conflict(message)
telegram.error.Conflict: Conflict: terminated by other getUpdates request; make sure that only one bot instance is running
ERROR:telegram.ext.updater:Error while getting Updates: Conflict: terminated by other getUpdates request; make sure that only one bot instance is running
ERROR:telegram.ext.dispatcher:No error handlers are registered, logging exception.
Traceback (most recent call last):
  File "C:\Users\Кирилл\AppData\Local\Programs\Python\Python39\lib\site-packages\telegram\ext\updater.py", line 646, in _network_loop_retry
    if not action_cb():
  File "C:\Users\Кирилл\AppData\Local\Programs\Python\Python39\lib\site-packages\telegram\ext\updater.py", line 597, in polling_action_cb
    updates = self.bot.get_updates(
  File "C:\Users\Кирилл\AppData\Local\Programs\Python\Python39\lib\site-packages\telegram\ext\extbot.py", line 222, in get_updates
    updates = super().get_updates(
  File "C:\Users\Кирилл\AppData\Local\Programs\Python\Python39\lib\site-packages\telegram\bot.py", line 130, in decorator
    result = func(*args, **kwargs)
  File "C:\Users\Кирилл\AppData\Local\Programs\Python\Python39\lib\site-packages\telegram\bot.py", line 2861, in get_updates
    self._post(
  File "C:\Users\Кирилл\AppData\Local\Programs\Python\Python39\lib\site-packages\telegram\bot.py", line 295, in _post
    return self.request.post(
  File "C:\Users\Кирилл\AppData\Local\Programs\Python\Python39\lib\site-packages\telegram\utils\request.py", line 356, in post
    result = self._request_wrapper(
  File "C:\Users\Кирилл\AppData\Local\Programs\Python\Python39\lib\site-packages\telegram\utils\request.py", line 283, in _request_wrapper
    raise Conflict(message)
telegram.error.Conflict: Conflict: terminated by other getUpdates request; make sure that only one bot instance is running
ERROR:telegram.ext.updater:Error while getting Updates: Conflict: terminated by other getUpdates request; make sure that only one bot instance is running
ERROR:telegram.ext.dispatcher:No error handlers are registered, logging exception.
Traceback (most recent call last):
  File "C:\Users\Кирилл\AppData\Local\Programs\Python\Python39\lib\site-packages\telegram\ext\updater.py", line 646, in _network_loop_retry
    if not action_cb():
  File "C:\Users\Кирилл\AppData\Local\Programs\Python\Python39\lib\site-packages\telegram\ext\updater.py", line 597, in polling_action_cb
    updates = self.bot.get_updates(
  File "C:\Users\Кирилл\AppData\Local\Programs\Python\Python39\lib\site-packages\telegram\ext\extbot.py", line 222, in get_updates
    updates = super().get_updates(
  File "C:\Users\Кирилл\AppData\Local\Programs\Python\Python39\lib\site-packages\telegram\bot.py", line 130, in decorator
    result = func(*args, **kwargs)
  File "C:\Users\Кирилл\AppData\Local\Programs\Python\Python39\lib\site-packages\telegram\bot.py", line 2861, in get_updates
    self._post(
  File "C:\Users\Кирилл\AppData\Local\Programs\Python\Python39\lib\site-packages\telegram\bot.py", line 295, in _post
    return self.request.post(
  File "C:\Users\Кирилл\AppData\Local\Programs\Python\Python39\lib\site-packages\telegram\utils\request.py", line 356, in post
    result = self._request_wrapper(
  File "C:\Users\Кирилл\AppData\Local\Programs\Python\Python39\lib\site-packages\telegram\utils\request.py", line 283, in _request_wrapper
    raise Conflict(message)
telegram.error.Conflict: Conflict: terminated by other getUpdates request; make sure that only one bot instance is running
ERROR:telegram.ext.updater:Error while getting Updates: Conflict: terminated by other getUpdates request; make sure that only one bot instance is running
ERROR:telegram.ext.dispatcher:No error handlers are registered, logging exception.
Traceback (most recent call last):
  File "C:\Users\Кирилл\AppData\Local\Programs\Python\Python39\lib\site-packages\telegram\ext\updater.py", line 646, in _network_loop_retry
    if not action_cb():
  File "C:\Users\Кирилл\AppData\Local\Programs\Python\Python39\lib\site-packages\telegram\ext\updater.py", line 597, in polling_action_cb
    updates = self.bot.get_updates(
  File "C:\Users\Кирилл\AppData\Local\Programs\Python\Python39\lib\site-packages\telegram\ext\extbot.py", line 222, in get_updates
    updates = super().get_updates(
  File "C:\Users\Кирилл\AppData\Local\Programs\Python\Python39\lib\site-packages\telegram\bot.py", line 130, in decorator
    result = func(*args, **kwargs)
  File "C:\Users\Кирилл\AppData\Local\Programs\Python\Python39\lib\site-packages\telegram\bot.py", line 2861, in get_updates
    self._post(
  File "C:\Users\Кирилл\AppData\Local\Programs\Python\Python39\lib\site-packages\telegram\bot.py", line 295, in _post
    return self.request.post(
  File "C:\Users\Кирилл\AppData\Local\Programs\Python\Python39\lib\site-packages\telegram\utils\request.py", line 356, in post
    result = self._request_wrapper(
  File "C:\Users\Кирилл\AppData\Local\Programs\Python\Python39\lib\site-packages\telegram\utils\request.py", line 283, in _request_wrapper
    raise Conflict(message)
telegram.error.Conflict: Conflict: terminated by other getUpdates request; make sure that only one bot instance is running
ERROR:telegram.ext.updater:Error while getting Updates: Conflict: terminated by other getUpdates request; make sure that only one bot instance is running
ERROR:telegram.ext.dispatcher:No error handlers are registered, logging exception.
Traceback (most recent call last):
  File "C:\Users\Кирилл\AppData\Local\Programs\Python\Python39\lib\site-packages\telegram\ext\updater.py", line 646, in _network_loop_retry
    if not action_cb():
  File "C:\Users\Кирилл\AppData\Local\Programs\Python\Python39\lib\site-packages\telegram\ext\updater.py", line 597, in polling_action_cb
    updates = self.bot.get_updates(
  File "C:\Users\Кирилл\AppData\Local\Programs\Python\Python39\lib\site-packages\telegram\ext\extbot.py", line 222, in get_updates
    updates = super().get_updates(
  File "C:\Users\Кирилл\AppData\Local\Programs\Python\Python39\lib\site-packages\telegram\bot.py", line 130, in decorator
    result = func(*args, **kwargs)
  File "C:\Users\Кирилл\AppData\Local\Programs\Python\Python39\lib\site-packages\telegram\bot.py", line 2861, in get_updates
    self._post(
  File "C:\Users\Кирилл\AppData\Local\Programs\Python\Python39\lib\site-packages\telegram\bot.py", line 295, in _post
    return self.request.post(
  File "C:\Users\Кирилл\AppData\Local\Programs\Python\Python39\lib\site-packages\telegram\utils\request.py", line 356, in post
    result = self._request_wrapper(
  File "C:\Users\Кирилл\AppData\Local\Programs\Python\Python39\lib\site-packages\telegram\utils\request.py", line 283, in _request_wrapper
    raise Conflict(message)
telegram.error.Conflict: Conflict: terminated by other getUpdates request; make sure that only one bot instance is running
ERROR:telegram.ext.updater:Error while getting Updates: Conflict: terminated by other getUpdates request; make sure that only one bot instance is running
ERROR:telegram.ext.dispatcher:No error handlers are registered, logging exception.
Traceback (most recent call last):
  File "C:\Users\Кирилл\AppData\Local\Programs\Python\Python39\lib\site-packages\telegram\ext\updater.py", line 646, in _network_loop_retry
    if not action_cb():
  File "C:\Users\Кирилл\AppData\Local\Programs\Python\Python39\lib\site-packages\telegram\ext\updater.py", line 597, in polling_action_cb
    updates = self.bot.get_updates(
  File "C:\Users\Кирилл\AppData\Local\Programs\Python\Python39\lib\site-packages\telegram\ext\extbot.py", line 222, in get_updates
    updates = super().get_updates(
  File "C:\Users\Кирилл\AppData\Local\Programs\Python\Python39\lib\site-packages\telegram\bot.py", line 130, in decorator
    result = func(*args, **kwargs)
  File "C:\Users\Кирилл\AppData\Local\Programs\Python\Python39\lib\site-packages\telegram\bot.py", line 2861, in get_updates
    self._post(
  File "C:\Users\Кирилл\AppData\Local\Programs\Python\Python39\lib\site-packages\telegram\bot.py", line 295, in _post
    return self.request.post(
  File "C:\Users\Кирилл\AppData\Local\Programs\Python\Python39\lib\site-packages\telegram\utils\request.py", line 356, in post
    result = self._request_wrapper(
  File "C:\Users\Кирилл\AppData\Local\Programs\Python\Python39\lib\site-packages\telegram\utils\request.py", line 283, in _request_wrapper
    raise Conflict(message)
telegram.error.Conflict: Conflict: terminated by other getUpdates request; make sure that only one bot instance is running
ERROR:telegram.ext.updater:Error while getting Updates: Conflict: terminated by other getUpdates request; make sure that only one bot instance is running
ERROR:telegram.ext.dispatcher:No error handlers are registered, logging exception.
Traceback (most recent call last):
  File "C:\Users\Кирилл\AppData\Local\Programs\Python\Python39\lib\site-packages\telegram\ext\updater.py", line 646, in _network_loop_retry
    if not action_cb():
  File "C:\Users\Кирилл\AppData\Local\Programs\Python\Python39\lib\site-packages\telegram\ext\updater.py", line 597, in polling_action_cb
    updates = self.bot.get_updates(
  File "C:\Users\Кирилл\AppData\Local\Programs\Python\Python39\lib\site-packages\telegram\ext\extbot.py", line 222, in get_updates
    updates = super().get_updates(
  File "C:\Users\Кирилл\AppData\Local\Programs\Python\Python39\lib\site-packages\telegram\bot.py", line 130, in decorator
    result = func(*args, **kwargs)
  File "C:\Users\Кирилл\AppData\Local\Programs\Python\Python39\lib\site-packages\telegram\bot.py", line 2861, in get_updates
    self._post(
  File "C:\Users\Кирилл\AppData\Local\Programs\Python\Python39\lib\site-packages\telegram\bot.py", line 295, in _post
    return self.request.post(
  File "C:\Users\Кирилл\AppData\Local\Programs\Python\Python39\lib\site-packages\telegram\utils\request.py", line 356, in post
    result = self._request_wrapper(
  File "C:\Users\Кирилл\AppData\Local\Programs\Python\Python39\lib\site-packages\telegram\utils\request.py", line 283, in _request_wrapper
    raise Conflict(message)
telegram.error.Conflict: Conflict: terminated by other getUpdates request; make sure that only one bot instance is running
ERROR:telegram.ext.updater:Error while getting Updates: Conflict: terminated by other getUpdates request; make sure that only one bot instance is running
ERROR:telegram.ext.dispatcher:No error handlers are registered, logging exception.
Traceback (most recent call last):
  File "C:\Users\Кирилл\AppData\Local\Programs\Python\Python39\lib\site-packages\telegram\ext\updater.py", line 646, in _network_loop_retry
    if not action_cb():
  File "C:\Users\Кирилл\AppData\Local\Programs\Python\Python39\lib\site-packages\telegram\ext\updater.py", line 597, in polling_action_cb
    updates = self.bot.get_updates(
  File "C:\Users\Кирилл\AppData\Local\Programs\Python\Python39\lib\site-packages\telegram\ext\extbot.py", line 222, in get_updates
    updates = super().get_updates(
  File "C:\Users\Кирилл\AppData\Local\Programs\Python\Python39\lib\site-packages\telegram\bot.py", line 130, in decorator
    result = func(*args, **kwargs)
  File "C:\Users\Кирилл\AppData\Local\Programs\Python\Python39\lib\site-packages\telegram\bot.py", line 2861, in get_updates
    self._post(
  File "C:\Users\Кирилл\AppData\Local\Programs\Python\Python39\lib\site-packages\telegram\bot.py", line 295, in _post
    return self.request.post(
  File "C:\Users\Кирилл\AppData\Local\Programs\Python\Python39\lib\site-packages\telegram\utils\request.py", line 356, in post
    result = self._request_wrapper(
  File "C:\Users\Кирилл\AppData\Local\Programs\Python\Python39\lib\site-packages\telegram\utils\request.py", line 283, in _request_wrapper
    raise Conflict(message)
telegram.error.Conflict: Conflict: terminated by other getUpdates request; make sure that only one bot instance is running
ERROR:telegram.ext.updater:Error while getting Updates: Conflict: terminated by other getUpdates request; make sure that only one bot instance is running
ERROR:telegram.ext.dispatcher:No error handlers are registered, logging exception.
Traceback (most recent call last):
  File "C:\Users\Кирилл\AppData\Local\Programs\Python\Python39\lib\site-packages\telegram\ext\updater.py", line 646, in _network_loop_retry
    if not action_cb():
  File "C:\Users\Кирилл\AppData\Local\Programs\Python\Python39\lib\site-packages\telegram\ext\updater.py", line 597, in polling_action_cb
    updates = self.bot.get_updates(
  File "C:\Users\Кирилл\AppData\Local\Programs\Python\Python39\lib\site-packages\telegram\ext\extbot.py", line 222, in get_updates
    updates = super().get_updates(
  File "C:\Users\Кирилл\AppData\Local\Programs\Python\Python39\lib\site-packages\telegram\bot.py", line 130, in decorator
    result = func(*args, **kwargs)
  File "C:\Users\Кирилл\AppData\Local\Programs\Python\Python39\lib\site-packages\telegram\bot.py", line 2861, in get_updates
    self._post(
  File "C:\Users\Кирилл\AppData\Local\Programs\Python\Python39\lib\site-packages\telegram\bot.py", line 295, in _post
    return self.request.post(
  File "C:\Users\Кирилл\AppData\Local\Programs\Python\Python39\lib\site-packages\telegram\utils\request.py", line 356, in post
    result = self._request_wrapper(
  File "C:\Users\Кирилл\AppData\Local\Programs\Python\Python39\lib\site-packages\telegram\utils\request.py", line 283, in _request_wrapper
    raise Conflict(message)
telegram.error.Conflict: Conflict: terminated by other getUpdates request; make sure that only one bot instance is running
ERROR:telegram.ext.updater:Error while getting Updates: Conflict: terminated by other getUpdates request; make sure that only one bot instance is running
ERROR:telegram.ext.dispatcher:No error handlers are registered, logging exception.
Traceback (most recent call last):
  File "C:\Users\Кирилл\AppData\Local\Programs\Python\Python39\lib\site-packages\telegram\ext\updater.py", line 646, in _network_loop_retry
    if not action_cb():
  File "C:\Users\Кирилл\AppData\Local\Programs\Python\Python39\lib\site-packages\telegram\ext\updater.py", line 597, in polling_action_cb
    updates = self.bot.get_updates(
  File "C:\Users\Кирилл\AppData\Local\Programs\Python\Python39\lib\site-packages\telegram\ext\extbot.py", line 222, in get_updates
    updates = super().get_updates(
  File "C:\Users\Кирилл\AppData\Local\Programs\Python\Python39\lib\site-packages\telegram\bot.py", line 130, in decorator
    result = func(*args, **kwargs)
  File "C:\Users\Кирилл\AppData\Local\Programs\Python\Python39\lib\site-packages\telegram\bot.py", line 2861, in get_updates
    self._post(
  File "C:\Users\Кирилл\AppData\Local\Programs\Python\Python39\lib\site-packages\telegram\bot.py", line 295, in _post
    return self.request.post(
  File "C:\Users\Кирилл\AppData\Local\Programs\Python\Python39\lib\site-packages\telegram\utils\request.py", line 356, in post
    result = self._request_wrapper(
  File "C:\Users\Кирилл\AppData\Local\Programs\Python\Python39\lib\site-packages\telegram\utils\request.py", line 283, in _request_wrapper
    raise Conflict(message)
telegram.error.Conflict: Conflict: terminated by other getUpdates request; make sure that only one bot instance is running
ERROR:telegram.ext.updater:Error while getting Updates: Conflict: terminated by other getUpdates request; make sure that only one bot instance is running
ERROR:telegram.ext.dispatcher:No error handlers are registered, logging exception.
Traceback (most recent call last):
  File "C:\Users\Кирилл\AppData\Local\Programs\Python\Python39\lib\site-packages\telegram\ext\updater.py", line 646, in _network_loop_retry
    if not action_cb():
  File "C:\Users\Кирилл\AppData\Local\Programs\Python\Python39\lib\site-packages\telegram\ext\updater.py", line 597, in polling_action_cb
    updates = self.bot.get_updates(
  File "C:\Users\Кирилл\AppData\Local\Programs\Python\Python39\lib\site-packages\telegram\ext\extbot.py", line 222, in get_updates
    updates = super().get_updates(
  File "C:\Users\Кирилл\AppData\Local\Programs\Python\Python39\lib\site-packages\telegram\bot.py", line 130, in decorator
    result = func(*args, **kwargs)
  File "C:\Users\Кирилл\AppData\Local\Programs\Python\Python39\lib\site-packages\telegram\bot.py", line 2861, in get_updates
    self._post(
  File "C:\Users\Кирилл\AppData\Local\Programs\Python\Python39\lib\site-packages\telegram\bot.py", line 295, in _post
    return self.request.post(
  File "C:\Users\Кирилл\AppData\Local\Programs\Python\Python39\lib\site-packages\telegram\utils\request.py", line 356, in post
    result = self._request_wrapper(
  File "C:\Users\Кирилл\AppData\Local\Programs\Python\Python39\lib\site-packages\telegram\utils\request.py", line 283, in _request_wrapper
    raise Conflict(message)
telegram.error.Conflict: Conflict: terminated by other getUpdates request; make sure that only one bot instance is running
ERROR:telegram.ext.updater:Error while getting Updates: Conflict: terminated by other getUpdates request; make sure that only one bot instance is running
ERROR:telegram.ext.dispatcher:No error handlers are registered, logging exception.
Traceback (most recent call last):
  File "C:\Users\Кирилл\AppData\Local\Programs\Python\Python39\lib\site-packages\telegram\ext\updater.py", line 646, in _network_loop_retry
    if not action_cb():
  File "C:\Users\Кирилл\AppData\Local\Programs\Python\Python39\lib\site-packages\telegram\ext\updater.py", line 597, in polling_action_cb
    updates = self.bot.get_updates(
  File "C:\Users\Кирилл\AppData\Local\Programs\Python\Python39\lib\site-packages\telegram\ext\extbot.py", line 222, in get_updates
    updates = super().get_updates(
  File "C:\Users\Кирилл\AppData\Local\Programs\Python\Python39\lib\site-packages\telegram\bot.py", line 130, in decorator
    result = func(*args, **kwargs)
  File "C:\Users\Кирилл\AppData\Local\Programs\Python\Python39\lib\site-packages\telegram\bot.py", line 2861, in get_updates
    self._post(
  File "C:\Users\Кирилл\AppData\Local\Programs\Python\Python39\lib\site-packages\telegram\bot.py", line 295, in _post
    return self.request.post(
  File "C:\Users\Кирилл\AppData\Local\Programs\Python\Python39\lib\site-packages\telegram\utils\request.py", line 356, in post
    result = self._request_wrapper(
  File "C:\Users\Кирилл\AppData\Local\Programs\Python\Python39\lib\site-packages\telegram\utils\request.py", line 283, in _request_wrapper
    raise Conflict(message)
telegram.error.Conflict: Conflict: terminated by other getUpdates request; make sure that only one bot instance is running
INFO:telegram.ext.updater:Received signal 2 (SIGINT), stopping...
INFO:apscheduler.scheduler:Scheduler has been shut down
INFO:root:Бот стартовал
INFO:apscheduler.scheduler:Scheduler started
INFO:root:Бот стартовал
INFO:apscheduler.scheduler:Scheduler started
WARNING:telegram.vendor.ptb_urllib3.urllib3.connectionpool:Retrying (Retry(total=2, connect=None, read=None, redirect=None)) after connection broken by 'ConnectTimeoutError(<telegram.vendor.ptb_urllib3.urllib3.contrib.socks.SOCKSHTTPSConnection object at 0x000002452D2C7F10>, 'Connection to api.telegram.org timed out. (connect timeout=5.0)')': /bot1902032740:AAGc8KON2bxjKnmukRVRt1acIC7kM1mVvCY/getUpdates
ERROR:telegram.ext.updater:Error while getting Updates: Conflict: terminated by other getUpdates request; make sure that only one bot instance is running
ERROR:telegram.ext.dispatcher:No error handlers are registered, logging exception.
Traceback (most recent call last):
  File "C:\Users\Кирилл\AppData\Local\Programs\Python\Python39\lib\site-packages\telegram\ext\updater.py", line 646, in _network_loop_retry
    if not action_cb():
  File "C:\Users\Кирилл\AppData\Local\Programs\Python\Python39\lib\site-packages\telegram\ext\updater.py", line 597, in polling_action_cb
    updates = self.bot.get_updates(
  File "C:\Users\Кирилл\AppData\Local\Programs\Python\Python39\lib\site-packages\telegram\ext\extbot.py", line 222, in get_updates
    updates = super().get_updates(
  File "C:\Users\Кирилл\AppData\Local\Programs\Python\Python39\lib\site-packages\telegram\bot.py", line 130, in decorator
    result = func(*args, **kwargs)
  File "C:\Users\Кирилл\AppData\Local\Programs\Python\Python39\lib\site-packages\telegram\bot.py", line 2861, in get_updates
    self._post(
  File "C:\Users\Кирилл\AppData\Local\Programs\Python\Python39\lib\site-packages\telegram\bot.py", line 295, in _post
    return self.request.post(
  File "C:\Users\Кирилл\AppData\Local\Programs\Python\Python39\lib\site-packages\telegram\utils\request.py", line 356, in post
    result = self._request_wrapper(
  File "C:\Users\Кирилл\AppData\Local\Programs\Python\Python39\lib\site-packages\telegram\utils\request.py", line 283, in _request_wrapper
    raise Conflict(message)
telegram.error.Conflict: Conflict: terminated by other getUpdates request; make sure that only one bot instance is running
ERROR:telegram.ext.updater:Error while getting Updates: Conflict: terminated by other getUpdates request; make sure that only one bot instance is running
ERROR:telegram.ext.dispatcher:No error handlers are registered, logging exception.
Traceback (most recent call last):
  File "C:\Users\Кирилл\AppData\Local\Programs\Python\Python39\lib\site-packages\telegram\ext\updater.py", line 646, in _network_loop_retry
    if not action_cb():
  File "C:\Users\Кирилл\AppData\Local\Programs\Python\Python39\lib\site-packages\telegram\ext\updater.py", line 597, in polling_action_cb
    updates = self.bot.get_updates(
  File "C:\Users\Кирилл\AppData\Local\Programs\Python\Python39\lib\site-packages\telegram\ext\extbot.py", line 222, in get_updates
    updates = super().get_updates(
  File "C:\Users\Кирилл\AppData\Local\Programs\Python\Python39\lib\site-packages\telegram\bot.py", line 130, in decorator
    result = func(*args, **kwargs)
  File "C:\Users\Кирилл\AppData\Local\Programs\Python\Python39\lib\site-packages\telegram\bot.py", line 2861, in get_updates
    self._post(
  File "C:\Users\Кирилл\AppData\Local\Programs\Python\Python39\lib\site-packages\telegram\bot.py", line 295, in _post
    return self.request.post(
  File "C:\Users\Кирилл\AppData\Local\Programs\Python\Python39\lib\site-packages\telegram\utils\request.py", line 356, in post
    result = self._request_wrapper(
  File "C:\Users\Кирилл\AppData\Local\Programs\Python\Python39\lib\site-packages\telegram\utils\request.py", line 283, in _request_wrapper
    raise Conflict(message)
telegram.error.Conflict: Conflict: terminated by other getUpdates request; make sure that only one bot instance is running
ERROR:telegram.ext.updater:Error while getting Updates: Conflict: terminated by other getUpdates request; make sure that only one bot instance is running
ERROR:telegram.ext.dispatcher:No error handlers are registered, logging exception.
Traceback (most recent call last):
  File "C:\Users\Кирилл\AppData\Local\Programs\Python\Python39\lib\site-packages\telegram\ext\updater.py", line 646, in _network_loop_retry
    if not action_cb():
  File "C:\Users\Кирилл\AppData\Local\Programs\Python\Python39\lib\site-packages\telegram\ext\updater.py", line 597, in polling_action_cb
    updates = self.bot.get_updates(
  File "C:\Users\Кирилл\AppData\Local\Programs\Python\Python39\lib\site-packages\telegram\ext\extbot.py", line 222, in get_updates
    updates = super().get_updates(
  File "C:\Users\Кирилл\AppData\Local\Programs\Python\Python39\lib\site-packages\telegram\bot.py", line 130, in decorator
    result = func(*args, **kwargs)
  File "C:\Users\Кирилл\AppData\Local\Programs\Python\Python39\lib\site-packages\telegram\bot.py", line 2861, in get_updates
    self._post(
  File "C:\Users\Кирилл\AppData\Local\Programs\Python\Python39\lib\site-packages\telegram\bot.py", line 295, in _post
    return self.request.post(
  File "C:\Users\Кирилл\AppData\Local\Programs\Python\Python39\lib\site-packages\telegram\utils\request.py", line 356, in post
    result = self._request_wrapper(
  File "C:\Users\Кирилл\AppData\Local\Programs\Python\Python39\lib\site-packages\telegram\utils\request.py", line 283, in _request_wrapper
    raise Conflict(message)
telegram.error.Conflict: Conflict: terminated by other getUpdates request; make sure that only one bot instance is running
ERROR:telegram.ext.updater:Error while getting Updates: Conflict: terminated by other getUpdates request; make sure that only one bot instance is running
ERROR:telegram.ext.dispatcher:No error handlers are registered, logging exception.
Traceback (most recent call last):
  File "C:\Users\Кирилл\AppData\Local\Programs\Python\Python39\lib\site-packages\telegram\ext\updater.py", line 646, in _network_loop_retry
    if not action_cb():
  File "C:\Users\Кирилл\AppData\Local\Programs\Python\Python39\lib\site-packages\telegram\ext\updater.py", line 597, in polling_action_cb
    updates = self.bot.get_updates(
  File "C:\Users\Кирилл\AppData\Local\Programs\Python\Python39\lib\site-packages\telegram\ext\extbot.py", line 222, in get_updates
    updates = super().get_updates(
  File "C:\Users\Кирилл\AppData\Local\Programs\Python\Python39\lib\site-packages\telegram\bot.py", line 130, in decorator
    result = func(*args, **kwargs)
  File "C:\Users\Кирилл\AppData\Local\Programs\Python\Python39\lib\site-packages\telegram\bot.py", line 2861, in get_updates
    self._post(
  File "C:\Users\Кирилл\AppData\Local\Programs\Python\Python39\lib\site-packages\telegram\bot.py", line 295, in _post
    return self.request.post(
  File "C:\Users\Кирилл\AppData\Local\Programs\Python\Python39\lib\site-packages\telegram\utils\request.py", line 356, in post
    result = self._request_wrapper(
  File "C:\Users\Кирилл\AppData\Local\Programs\Python\Python39\lib\site-packages\telegram\utils\request.py", line 283, in _request_wrapper
    raise Conflict(message)
telegram.error.Conflict: Conflict: terminated by other getUpdates request; make sure that only one bot instance is running
ERROR:telegram.ext.updater:Error while getting Updates: Conflict: terminated by other getUpdates request; make sure that only one bot instance is running
ERROR:telegram.ext.dispatcher:No error handlers are registered, logging exception.
Traceback (most recent call last):
  File "C:\Users\Кирилл\AppData\Local\Programs\Python\Python39\lib\site-packages\telegram\ext\updater.py", line 646, in _network_loop_retry
    if not action_cb():
  File "C:\Users\Кирилл\AppData\Local\Programs\Python\Python39\lib\site-packages\telegram\ext\updater.py", line 597, in polling_action_cb
    updates = self.bot.get_updates(
  File "C:\Users\Кирилл\AppData\Local\Programs\Python\Python39\lib\site-packages\telegram\ext\extbot.py", line 222, in get_updates
    updates = super().get_updates(
  File "C:\Users\Кирилл\AppData\Local\Programs\Python\Python39\lib\site-packages\telegram\bot.py", line 130, in decorator
    result = func(*args, **kwargs)
  File "C:\Users\Кирилл\AppData\Local\Programs\Python\Python39\lib\site-packages\telegram\bot.py", line 2861, in get_updates
    self._post(
  File "C:\Users\Кирилл\AppData\Local\Programs\Python\Python39\lib\site-packages\telegram\bot.py", line 295, in _post
    return self.request.post(
  File "C:\Users\Кирилл\AppData\Local\Programs\Python\Python39\lib\site-packages\telegram\utils\request.py", line 356, in post
    result = self._request_wrapper(
  File "C:\Users\Кирилл\AppData\Local\Programs\Python\Python39\lib\site-packages\telegram\utils\request.py", line 283, in _request_wrapper
    raise Conflict(message)
telegram.error.Conflict: Conflict: terminated by other getUpdates request; make sure that only one bot instance is running
ERROR:telegram.ext.updater:Error while getting Updates: Conflict: terminated by other getUpdates request; make sure that only one bot instance is running
ERROR:telegram.ext.dispatcher:No error handlers are registered, logging exception.
Traceback (most recent call last):
  File "C:\Users\Кирилл\AppData\Local\Programs\Python\Python39\lib\site-packages\telegram\ext\updater.py", line 646, in _network_loop_retry
    if not action_cb():
  File "C:\Users\Кирилл\AppData\Local\Programs\Python\Python39\lib\site-packages\telegram\ext\updater.py", line 597, in polling_action_cb
    updates = self.bot.get_updates(
  File "C:\Users\Кирилл\AppData\Local\Programs\Python\Python39\lib\site-packages\telegram\ext\extbot.py", line 222, in get_updates
    updates = super().get_updates(
  File "C:\Users\Кирилл\AppData\Local\Programs\Python\Python39\lib\site-packages\telegram\bot.py", line 130, in decorator
    result = func(*args, **kwargs)
  File "C:\Users\Кирилл\AppData\Local\Programs\Python\Python39\lib\site-packages\telegram\bot.py", line 2861, in get_updates
    self._post(
  File "C:\Users\Кирилл\AppData\Local\Programs\Python\Python39\lib\site-packages\telegram\bot.py", line 295, in _post
    return self.request.post(
  File "C:\Users\Кирилл\AppData\Local\Programs\Python\Python39\lib\site-packages\telegram\utils\request.py", line 356, in post
    result = self._request_wrapper(
  File "C:\Users\Кирилл\AppData\Local\Programs\Python\Python39\lib\site-packages\telegram\utils\request.py", line 283, in _request_wrapper
    raise Conflict(message)
telegram.error.Conflict: Conflict: terminated by other getUpdates request; make sure that only one bot instance is running
ERROR:telegram.ext.updater:Error while getting Updates: Conflict: terminated by other getUpdates request; make sure that only one bot instance is running
ERROR:telegram.ext.dispatcher:No error handlers are registered, logging exception.
Traceback (most recent call last):
  File "C:\Users\Кирилл\AppData\Local\Programs\Python\Python39\lib\site-packages\telegram\ext\updater.py", line 646, in _network_loop_retry
    if not action_cb():
  File "C:\Users\Кирилл\AppData\Local\Programs\Python\Python39\lib\site-packages\telegram\ext\updater.py", line 597, in polling_action_cb
    updates = self.bot.get_updates(
  File "C:\Users\Кирилл\AppData\Local\Programs\Python\Python39\lib\site-packages\telegram\ext\extbot.py", line 222, in get_updates
    updates = super().get_updates(
  File "C:\Users\Кирилл\AppData\Local\Programs\Python\Python39\lib\site-packages\telegram\bot.py", line 130, in decorator
    result = func(*args, **kwargs)
  File "C:\Users\Кирилл\AppData\Local\Programs\Python\Python39\lib\site-packages\telegram\bot.py", line 2861, in get_updates
    self._post(
  File "C:\Users\Кирилл\AppData\Local\Programs\Python\Python39\lib\site-packages\telegram\bot.py", line 295, in _post
    return self.request.post(
  File "C:\Users\Кирилл\AppData\Local\Programs\Python\Python39\lib\site-packages\telegram\utils\request.py", line 356, in post
    result = self._request_wrapper(
  File "C:\Users\Кирилл\AppData\Local\Programs\Python\Python39\lib\site-packages\telegram\utils\request.py", line 283, in _request_wrapper
    raise Conflict(message)
telegram.error.Conflict: Conflict: terminated by other getUpdates request; make sure that only one bot instance is running
ERROR:telegram.ext.updater:Error while getting Updates: Conflict: terminated by other getUpdates request; make sure that only one bot instance is running
ERROR:telegram.ext.dispatcher:No error handlers are registered, logging exception.
Traceback (most recent call last):
  File "C:\Users\Кирилл\AppData\Local\Programs\Python\Python39\lib\site-packages\telegram\ext\updater.py", line 646, in _network_loop_retry
    if not action_cb():
  File "C:\Users\Кирилл\AppData\Local\Programs\Python\Python39\lib\site-packages\telegram\ext\updater.py", line 597, in polling_action_cb
    updates = self.bot.get_updates(
  File "C:\Users\Кирилл\AppData\Local\Programs\Python\Python39\lib\site-packages\telegram\ext\extbot.py", line 222, in get_updates
    updates = super().get_updates(
  File "C:\Users\Кирилл\AppData\Local\Programs\Python\Python39\lib\site-packages\telegram\bot.py", line 130, in decorator
    result = func(*args, **kwargs)
  File "C:\Users\Кирилл\AppData\Local\Programs\Python\Python39\lib\site-packages\telegram\bot.py", line 2861, in get_updates
    self._post(
  File "C:\Users\Кирилл\AppData\Local\Programs\Python\Python39\lib\site-packages\telegram\bot.py", line 295, in _post
    return self.request.post(
  File "C:\Users\Кирилл\AppData\Local\Programs\Python\Python39\lib\site-packages\telegram\utils\request.py", line 356, in post
    result = self._request_wrapper(
  File "C:\Users\Кирилл\AppData\Local\Programs\Python\Python39\lib\site-packages\telegram\utils\request.py", line 283, in _request_wrapper
    raise Conflict(message)
telegram.error.Conflict: Conflict: terminated by other getUpdates request; make sure that only one bot instance is running
ERROR:telegram.ext.updater:Error while getting Updates: Conflict: terminated by other getUpdates request; make sure that only one bot instance is running
ERROR:telegram.ext.dispatcher:No error handlers are registered, logging exception.
Traceback (most recent call last):
  File "C:\Users\Кирилл\AppData\Local\Programs\Python\Python39\lib\site-packages\telegram\ext\updater.py", line 646, in _network_loop_retry
    if not action_cb():
  File "C:\Users\Кирилл\AppData\Local\Programs\Python\Python39\lib\site-packages\telegram\ext\updater.py", line 597, in polling_action_cb
    updates = self.bot.get_updates(
  File "C:\Users\Кирилл\AppData\Local\Programs\Python\Python39\lib\site-packages\telegram\ext\extbot.py", line 222, in get_updates
    updates = super().get_updates(
  File "C:\Users\Кирилл\AppData\Local\Programs\Python\Python39\lib\site-packages\telegram\bot.py", line 130, in decorator
    result = func(*args, **kwargs)
  File "C:\Users\Кирилл\AppData\Local\Programs\Python\Python39\lib\site-packages\telegram\bot.py", line 2861, in get_updates
    self._post(
  File "C:\Users\Кирилл\AppData\Local\Programs\Python\Python39\lib\site-packages\telegram\bot.py", line 295, in _post
    return self.request.post(
  File "C:\Users\Кирилл\AppData\Local\Programs\Python\Python39\lib\site-packages\telegram\utils\request.py", line 356, in post
    result = self._request_wrapper(
  File "C:\Users\Кирилл\AppData\Local\Programs\Python\Python39\lib\site-packages\telegram\utils\request.py", line 283, in _request_wrapper
    raise Conflict(message)
telegram.error.Conflict: Conflict: terminated by other getUpdates request; make sure that only one bot instance is running
ERROR:telegram.ext.updater:Error while getting Updates: Conflict: terminated by other getUpdates request; make sure that only one bot instance is running
ERROR:telegram.ext.dispatcher:No error handlers are registered, logging exception.
Traceback (most recent call last):
  File "C:\Users\Кирилл\AppData\Local\Programs\Python\Python39\lib\site-packages\telegram\ext\updater.py", line 646, in _network_loop_retry
    if not action_cb():
  File "C:\Users\Кирилл\AppData\Local\Programs\Python\Python39\lib\site-packages\telegram\ext\updater.py", line 597, in polling_action_cb
    updates = self.bot.get_updates(
  File "C:\Users\Кирилл\AppData\Local\Programs\Python\Python39\lib\site-packages\telegram\ext\extbot.py", line 222, in get_updates
    updates = super().get_updates(
  File "C:\Users\Кирилл\AppData\Local\Programs\Python\Python39\lib\site-packages\telegram\bot.py", line 130, in decorator
    result = func(*args, **kwargs)
  File "C:\Users\Кирилл\AppData\Local\Programs\Python\Python39\lib\site-packages\telegram\bot.py", line 2861, in get_updates
    self._post(
  File "C:\Users\Кирилл\AppData\Local\Programs\Python\Python39\lib\site-packages\telegram\bot.py", line 295, in _post
    return self.request.post(
  File "C:\Users\Кирилл\AppData\Local\Programs\Python\Python39\lib\site-packages\telegram\utils\request.py", line 356, in post
    result = self._request_wrapper(
  File "C:\Users\Кирилл\AppData\Local\Programs\Python\Python39\lib\site-packages\telegram\utils\request.py", line 283, in _request_wrapper
    raise Conflict(message)
telegram.error.Conflict: Conflict: terminated by other getUpdates request; make sure that only one bot instance is running
ERROR:telegram.ext.updater:Error while getting Updates: Conflict: terminated by other getUpdates request; make sure that only one bot instance is running
ERROR:telegram.ext.dispatcher:No error handlers are registered, logging exception.
Traceback (most recent call last):
  File "C:\Users\Кирилл\AppData\Local\Programs\Python\Python39\lib\site-packages\telegram\ext\updater.py", line 646, in _network_loop_retry
    if not action_cb():
  File "C:\Users\Кирилл\AppData\Local\Programs\Python\Python39\lib\site-packages\telegram\ext\updater.py", line 597, in polling_action_cb
    updates = self.bot.get_updates(
  File "C:\Users\Кирилл\AppData\Local\Programs\Python\Python39\lib\site-packages\telegram\ext\extbot.py", line 222, in get_updates
    updates = super().get_updates(
  File "C:\Users\Кирилл\AppData\Local\Programs\Python\Python39\lib\site-packages\telegram\bot.py", line 130, in decorator
    result = func(*args, **kwargs)
  File "C:\Users\Кирилл\AppData\Local\Programs\Python\Python39\lib\site-packages\telegram\bot.py", line 2861, in get_updates
    self._post(
  File "C:\Users\Кирилл\AppData\Local\Programs\Python\Python39\lib\site-packages\telegram\bot.py", line 295, in _post
    return self.request.post(
  File "C:\Users\Кирилл\AppData\Local\Programs\Python\Python39\lib\site-packages\telegram\utils\request.py", line 356, in post
    result = self._request_wrapper(
  File "C:\Users\Кирилл\AppData\Local\Programs\Python\Python39\lib\site-packages\telegram\utils\request.py", line 283, in _request_wrapper
    raise Conflict(message)
telegram.error.Conflict: Conflict: terminated by other getUpdates request; make sure that only one bot instance is running
ERROR:telegram.ext.updater:Error while getting Updates: Conflict: terminated by other getUpdates request; make sure that only one bot instance is running
ERROR:telegram.ext.dispatcher:No error handlers are registered, logging exception.
Traceback (most recent call last):
  File "C:\Users\Кирилл\AppData\Local\Programs\Python\Python39\lib\site-packages\telegram\ext\updater.py", line 646, in _network_loop_retry
    if not action_cb():
  File "C:\Users\Кирилл\AppData\Local\Programs\Python\Python39\lib\site-packages\telegram\ext\updater.py", line 597, in polling_action_cb
    updates = self.bot.get_updates(
  File "C:\Users\Кирилл\AppData\Local\Programs\Python\Python39\lib\site-packages\telegram\ext\extbot.py", line 222, in get_updates
    updates = super().get_updates(
  File "C:\Users\Кирилл\AppData\Local\Programs\Python\Python39\lib\site-packages\telegram\bot.py", line 130, in decorator
    result = func(*args, **kwargs)
  File "C:\Users\Кирилл\AppData\Local\Programs\Python\Python39\lib\site-packages\telegram\bot.py", line 2861, in get_updates
    self._post(
  File "C:\Users\Кирилл\AppData\Local\Programs\Python\Python39\lib\site-packages\telegram\bot.py", line 295, in _post
    return self.request.post(
  File "C:\Users\Кирилл\AppData\Local\Programs\Python\Python39\lib\site-packages\telegram\utils\request.py", line 356, in post
    result = self._request_wrapper(
  File "C:\Users\Кирилл\AppData\Local\Programs\Python\Python39\lib\site-packages\telegram\utils\request.py", line 283, in _request_wrapper
    raise Conflict(message)
telegram.error.Conflict: Conflict: terminated by other getUpdates request; make sure that only one bot instance is running
ERROR:telegram.ext.updater:Error while getting Updates: Conflict: terminated by other getUpdates request; make sure that only one bot instance is running
ERROR:telegram.ext.dispatcher:No error handlers are registered, logging exception.
Traceback (most recent call last):
  File "C:\Users\Кирилл\AppData\Local\Programs\Python\Python39\lib\site-packages\telegram\ext\updater.py", line 646, in _network_loop_retry
    if not action_cb():
  File "C:\Users\Кирилл\AppData\Local\Programs\Python\Python39\lib\site-packages\telegram\ext\updater.py", line 597, in polling_action_cb
    updates = self.bot.get_updates(
  File "C:\Users\Кирилл\AppData\Local\Programs\Python\Python39\lib\site-packages\telegram\ext\extbot.py", line 222, in get_updates
    updates = super().get_updates(
  File "C:\Users\Кирилл\AppData\Local\Programs\Python\Python39\lib\site-packages\telegram\bot.py", line 130, in decorator
    result = func(*args, **kwargs)
  File "C:\Users\Кирилл\AppData\Local\Programs\Python\Python39\lib\site-packages\telegram\bot.py", line 2861, in get_updates
    self._post(
  File "C:\Users\Кирилл\AppData\Local\Programs\Python\Python39\lib\site-packages\telegram\bot.py", line 295, in _post
    return self.request.post(
  File "C:\Users\Кирилл\AppData\Local\Programs\Python\Python39\lib\site-packages\telegram\utils\request.py", line 356, in post
    result = self._request_wrapper(
  File "C:\Users\Кирилл\AppData\Local\Programs\Python\Python39\lib\site-packages\telegram\utils\request.py", line 283, in _request_wrapper
    raise Conflict(message)
telegram.error.Conflict: Conflict: terminated by other getUpdates request; make sure that only one bot instance is running
ERROR:telegram.ext.updater:Error while getting Updates: Conflict: terminated by other getUpdates request; make sure that only one bot instance is running
ERROR:telegram.ext.dispatcher:No error handlers are registered, logging exception.
Traceback (most recent call last):
  File "C:\Users\Кирилл\AppData\Local\Programs\Python\Python39\lib\site-packages\telegram\ext\updater.py", line 646, in _network_loop_retry
    if not action_cb():
  File "C:\Users\Кирилл\AppData\Local\Programs\Python\Python39\lib\site-packages\telegram\ext\updater.py", line 597, in polling_action_cb
    updates = self.bot.get_updates(
  File "C:\Users\Кирилл\AppData\Local\Programs\Python\Python39\lib\site-packages\telegram\ext\extbot.py", line 222, in get_updates
    updates = super().get_updates(
  File "C:\Users\Кирилл\AppData\Local\Programs\Python\Python39\lib\site-packages\telegram\bot.py", line 130, in decorator
    result = func(*args, **kwargs)
  File "C:\Users\Кирилл\AppData\Local\Programs\Python\Python39\lib\site-packages\telegram\bot.py", line 2861, in get_updates
    self._post(
  File "C:\Users\Кирилл\AppData\Local\Programs\Python\Python39\lib\site-packages\telegram\bot.py", line 295, in _post
    return self.request.post(
  File "C:\Users\Кирилл\AppData\Local\Programs\Python\Python39\lib\site-packages\telegram\utils\request.py", line 356, in post
    result = self._request_wrapper(
  File "C:\Users\Кирилл\AppData\Local\Programs\Python\Python39\lib\site-packages\telegram\utils\request.py", line 283, in _request_wrapper
    raise Conflict(message)
telegram.error.Conflict: Conflict: terminated by other getUpdates request; make sure that only one bot instance is running
ERROR:telegram.ext.updater:Error while getting Updates: Conflict: terminated by other getUpdates request; make sure that only one bot instance is running
ERROR:telegram.ext.dispatcher:No error handlers are registered, logging exception.
Traceback (most recent call last):
  File "C:\Users\Кирилл\AppData\Local\Programs\Python\Python39\lib\site-packages\telegram\ext\updater.py", line 646, in _network_loop_retry
    if not action_cb():
  File "C:\Users\Кирилл\AppData\Local\Programs\Python\Python39\lib\site-packages\telegram\ext\updater.py", line 597, in polling_action_cb
    updates = self.bot.get_updates(
  File "C:\Users\Кирилл\AppData\Local\Programs\Python\Python39\lib\site-packages\telegram\ext\extbot.py", line 222, in get_updates
    updates = super().get_updates(
  File "C:\Users\Кирилл\AppData\Local\Programs\Python\Python39\lib\site-packages\telegram\bot.py", line 130, in decorator
    result = func(*args, **kwargs)
  File "C:\Users\Кирилл\AppData\Local\Programs\Python\Python39\lib\site-packages\telegram\bot.py", line 2861, in get_updates
    self._post(
  File "C:\Users\Кирилл\AppData\Local\Programs\Python\Python39\lib\site-packages\telegram\bot.py", line 295, in _post
    return self.request.post(
  File "C:\Users\Кирилл\AppData\Local\Programs\Python\Python39\lib\site-packages\telegram\utils\request.py", line 356, in post
    result = self._request_wrapper(
  File "C:\Users\Кирилл\AppData\Local\Programs\Python\Python39\lib\site-packages\telegram\utils\request.py", line 283, in _request_wrapper
    raise Conflict(message)
telegram.error.Conflict: Conflict: terminated by other getUpdates request; make sure that only one bot instance is running
ERROR:telegram.ext.updater:Error while getting Updates: Conflict: terminated by other getUpdates request; make sure that only one bot instance is running
ERROR:telegram.ext.dispatcher:No error handlers are registered, logging exception.
Traceback (most recent call last):
  File "C:\Users\Кирилл\AppData\Local\Programs\Python\Python39\lib\site-packages\telegram\ext\updater.py", line 646, in _network_loop_retry
    if not action_cb():
  File "C:\Users\Кирилл\AppData\Local\Programs\Python\Python39\lib\site-packages\telegram\ext\updater.py", line 597, in polling_action_cb
    updates = self.bot.get_updates(
  File "C:\Users\Кирилл\AppData\Local\Programs\Python\Python39\lib\site-packages\telegram\ext\extbot.py", line 222, in get_updates
    updates = super().get_updates(
  File "C:\Users\Кирилл\AppData\Local\Programs\Python\Python39\lib\site-packages\telegram\bot.py", line 130, in decorator
    result = func(*args, **kwargs)
  File "C:\Users\Кирилл\AppData\Local\Programs\Python\Python39\lib\site-packages\telegram\bot.py", line 2861, in get_updates
    self._post(
  File "C:\Users\Кирилл\AppData\Local\Programs\Python\Python39\lib\site-packages\telegram\bot.py", line 295, in _post
    return self.request.post(
  File "C:\Users\Кирилл\AppData\Local\Programs\Python\Python39\lib\site-packages\telegram\utils\request.py", line 356, in post
    result = self._request_wrapper(
  File "C:\Users\Кирилл\AppData\Local\Programs\Python\Python39\lib\site-packages\telegram\utils\request.py", line 283, in _request_wrapper
    raise Conflict(message)
telegram.error.Conflict: Conflict: terminated by other getUpdates request; make sure that only one bot instance is running
ERROR:telegram.ext.updater:Error while getting Updates: Conflict: terminated by other getUpdates request; make sure that only one bot instance is running
ERROR:telegram.ext.dispatcher:No error handlers are registered, logging exception.
Traceback (most recent call last):
  File "C:\Users\Кирилл\AppData\Local\Programs\Python\Python39\lib\site-packages\telegram\ext\updater.py", line 646, in _network_loop_retry
    if not action_cb():
  File "C:\Users\Кирилл\AppData\Local\Programs\Python\Python39\lib\site-packages\telegram\ext\updater.py", line 597, in polling_action_cb
    updates = self.bot.get_updates(
  File "C:\Users\Кирилл\AppData\Local\Programs\Python\Python39\lib\site-packages\telegram\ext\extbot.py", line 222, in get_updates
    updates = super().get_updates(
  File "C:\Users\Кирилл\AppData\Local\Programs\Python\Python39\lib\site-packages\telegram\bot.py", line 130, in decorator
    result = func(*args, **kwargs)
  File "C:\Users\Кирилл\AppData\Local\Programs\Python\Python39\lib\site-packages\telegram\bot.py", line 2861, in get_updates
    self._post(
  File "C:\Users\Кирилл\AppData\Local\Programs\Python\Python39\lib\site-packages\telegram\bot.py", line 295, in _post
    return self.request.post(
  File "C:\Users\Кирилл\AppData\Local\Programs\Python\Python39\lib\site-packages\telegram\utils\request.py", line 356, in post
    result = self._request_wrapper(
  File "C:\Users\Кирилл\AppData\Local\Programs\Python\Python39\lib\site-packages\telegram\utils\request.py", line 283, in _request_wrapper
    raise Conflict(message)
telegram.error.Conflict: Conflict: terminated by other getUpdates request; make sure that only one bot instance is running
ERROR:telegram.ext.updater:Error while getting Updates: Conflict: terminated by other getUpdates request; make sure that only one bot instance is running
ERROR:telegram.ext.dispatcher:No error handlers are registered, logging exception.
Traceback (most recent call last):
  File "C:\Users\Кирилл\AppData\Local\Programs\Python\Python39\lib\site-packages\telegram\ext\updater.py", line 646, in _network_loop_retry
    if not action_cb():
  File "C:\Users\Кирилл\AppData\Local\Programs\Python\Python39\lib\site-packages\telegram\ext\updater.py", line 597, in polling_action_cb
    updates = self.bot.get_updates(
  File "C:\Users\Кирилл\AppData\Local\Programs\Python\Python39\lib\site-packages\telegram\ext\extbot.py", line 222, in get_updates
    updates = super().get_updates(
  File "C:\Users\Кирилл\AppData\Local\Programs\Python\Python39\lib\site-packages\telegram\bot.py", line 130, in decorator
    result = func(*args, **kwargs)
  File "C:\Users\Кирилл\AppData\Local\Programs\Python\Python39\lib\site-packages\telegram\bot.py", line 2861, in get_updates
    self._post(
  File "C:\Users\Кирилл\AppData\Local\Programs\Python\Python39\lib\site-packages\telegram\bot.py", line 295, in _post
    return self.request.post(
  File "C:\Users\Кирилл\AppData\Local\Programs\Python\Python39\lib\site-packages\telegram\utils\request.py", line 356, in post
    result = self._request_wrapper(
  File "C:\Users\Кирилл\AppData\Local\Programs\Python\Python39\lib\site-packages\telegram\utils\request.py", line 283, in _request_wrapper
    raise Conflict(message)
telegram.error.Conflict: Conflict: terminated by other getUpdates request; make sure that only one bot instance is running
ERROR:telegram.ext.updater:Error while getting Updates: Conflict: terminated by other getUpdates request; make sure that only one bot instance is running
ERROR:telegram.ext.dispatcher:No error handlers are registered, logging exception.
Traceback (most recent call last):
  File "C:\Users\Кирилл\AppData\Local\Programs\Python\Python39\lib\site-packages\telegram\ext\updater.py", line 646, in _network_loop_retry
    if not action_cb():
  File "C:\Users\Кирилл\AppData\Local\Programs\Python\Python39\lib\site-packages\telegram\ext\updater.py", line 597, in polling_action_cb
    updates = self.bot.get_updates(
  File "C:\Users\Кирилл\AppData\Local\Programs\Python\Python39\lib\site-packages\telegram\ext\extbot.py", line 222, in get_updates
    updates = super().get_updates(
  File "C:\Users\Кирилл\AppData\Local\Programs\Python\Python39\lib\site-packages\telegram\bot.py", line 130, in decorator
    result = func(*args, **kwargs)
  File "C:\Users\Кирилл\AppData\Local\Programs\Python\Python39\lib\site-packages\telegram\bot.py", line 2861, in get_updates
    self._post(
  File "C:\Users\Кирилл\AppData\Local\Programs\Python\Python39\lib\site-packages\telegram\bot.py", line 295, in _post
    return self.request.post(
  File "C:\Users\Кирилл\AppData\Local\Programs\Python\Python39\lib\site-packages\telegram\utils\request.py", line 356, in post
    result = self._request_wrapper(
  File "C:\Users\Кирилл\AppData\Local\Programs\Python\Python39\lib\site-packages\telegram\utils\request.py", line 283, in _request_wrapper
    raise Conflict(message)
telegram.error.Conflict: Conflict: terminated by other getUpdates request; make sure that only one bot instance is running
ERROR:telegram.ext.updater:Error while getting Updates: Conflict: terminated by other getUpdates request; make sure that only one bot instance is running
ERROR:telegram.ext.dispatcher:No error handlers are registered, logging exception.
Traceback (most recent call last):
  File "C:\Users\Кирилл\AppData\Local\Programs\Python\Python39\lib\site-packages\telegram\ext\updater.py", line 646, in _network_loop_retry
    if not action_cb():
  File "C:\Users\Кирилл\AppData\Local\Programs\Python\Python39\lib\site-packages\telegram\ext\updater.py", line 597, in polling_action_cb
    updates = self.bot.get_updates(
  File "C:\Users\Кирилл\AppData\Local\Programs\Python\Python39\lib\site-packages\telegram\ext\extbot.py", line 222, in get_updates
    updates = super().get_updates(
  File "C:\Users\Кирилл\AppData\Local\Programs\Python\Python39\lib\site-packages\telegram\bot.py", line 130, in decorator
    result = func(*args, **kwargs)
  File "C:\Users\Кирилл\AppData\Local\Programs\Python\Python39\lib\site-packages\telegram\bot.py", line 2861, in get_updates
    self._post(
  File "C:\Users\Кирилл\AppData\Local\Programs\Python\Python39\lib\site-packages\telegram\bot.py", line 295, in _post
    return self.request.post(
  File "C:\Users\Кирилл\AppData\Local\Programs\Python\Python39\lib\site-packages\telegram\utils\request.py", line 356, in post
    result = self._request_wrapper(
  File "C:\Users\Кирилл\AppData\Local\Programs\Python\Python39\lib\site-packages\telegram\utils\request.py", line 283, in _request_wrapper
    raise Conflict(message)
telegram.error.Conflict: Conflict: terminated by other getUpdates request; make sure that only one bot instance is running
ERROR:telegram.ext.updater:Error while getting Updates: Conflict: terminated by other getUpdates request; make sure that only one bot instance is running
ERROR:telegram.ext.dispatcher:No error handlers are registered, logging exception.
Traceback (most recent call last):
  File "C:\Users\Кирилл\AppData\Local\Programs\Python\Python39\lib\site-packages\telegram\ext\updater.py", line 646, in _network_loop_retry
    if not action_cb():
  File "C:\Users\Кирилл\AppData\Local\Programs\Python\Python39\lib\site-packages\telegram\ext\updater.py", line 597, in polling_action_cb
    updates = self.bot.get_updates(
  File "C:\Users\Кирилл\AppData\Local\Programs\Python\Python39\lib\site-packages\telegram\ext\extbot.py", line 222, in get_updates
    updates = super().get_updates(
  File "C:\Users\Кирилл\AppData\Local\Programs\Python\Python39\lib\site-packages\telegram\bot.py", line 130, in decorator
    result = func(*args, **kwargs)
  File "C:\Users\Кирилл\AppData\Local\Programs\Python\Python39\lib\site-packages\telegram\bot.py", line 2861, in get_updates
    self._post(
  File "C:\Users\Кирилл\AppData\Local\Programs\Python\Python39\lib\site-packages\telegram\bot.py", line 295, in _post
    return self.request.post(
  File "C:\Users\Кирилл\AppData\Local\Programs\Python\Python39\lib\site-packages\telegram\utils\request.py", line 356, in post
    result = self._request_wrapper(
  File "C:\Users\Кирилл\AppData\Local\Programs\Python\Python39\lib\site-packages\telegram\utils\request.py", line 283, in _request_wrapper
    raise Conflict(message)
telegram.error.Conflict: Conflict: terminated by other getUpdates request; make sure that only one bot instance is running
ERROR:telegram.ext.updater:Error while getting Updates: Conflict: terminated by other getUpdates request; make sure that only one bot instance is running
ERROR:telegram.ext.dispatcher:No error handlers are registered, logging exception.
Traceback (most recent call last):
  File "C:\Users\Кирилл\AppData\Local\Programs\Python\Python39\lib\site-packages\telegram\ext\updater.py", line 646, in _network_loop_retry
    if not action_cb():
  File "C:\Users\Кирилл\AppData\Local\Programs\Python\Python39\lib\site-packages\telegram\ext\updater.py", line 597, in polling_action_cb
    updates = self.bot.get_updates(
  File "C:\Users\Кирилл\AppData\Local\Programs\Python\Python39\lib\site-packages\telegram\ext\extbot.py", line 222, in get_updates
    updates = super().get_updates(
  File "C:\Users\Кирилл\AppData\Local\Programs\Python\Python39\lib\site-packages\telegram\bot.py", line 130, in decorator
    result = func(*args, **kwargs)
  File "C:\Users\Кирилл\AppData\Local\Programs\Python\Python39\lib\site-packages\telegram\bot.py", line 2861, in get_updates
    self._post(
  File "C:\Users\Кирилл\AppData\Local\Programs\Python\Python39\lib\site-packages\telegram\bot.py", line 295, in _post
    return self.request.post(
  File "C:\Users\Кирилл\AppData\Local\Programs\Python\Python39\lib\site-packages\telegram\utils\request.py", line 356, in post
    result = self._request_wrapper(
  File "C:\Users\Кирилл\AppData\Local\Programs\Python\Python39\lib\site-packages\telegram\utils\request.py", line 283, in _request_wrapper
    raise Conflict(message)
telegram.error.Conflict: Conflict: terminated by other getUpdates request; make sure that only one bot instance is running
ERROR:telegram.ext.updater:Error while getting Updates: Conflict: terminated by other getUpdates request; make sure that only one bot instance is running
ERROR:telegram.ext.dispatcher:No error handlers are registered, logging exception.
Traceback (most recent call last):
  File "C:\Users\Кирилл\AppData\Local\Programs\Python\Python39\lib\site-packages\telegram\ext\updater.py", line 646, in _network_loop_retry
    if not action_cb():
  File "C:\Users\Кирилл\AppData\Local\Programs\Python\Python39\lib\site-packages\telegram\ext\updater.py", line 597, in polling_action_cb
    updates = self.bot.get_updates(
  File "C:\Users\Кирилл\AppData\Local\Programs\Python\Python39\lib\site-packages\telegram\ext\extbot.py", line 222, in get_updates
    updates = super().get_updates(
  File "C:\Users\Кирилл\AppData\Local\Programs\Python\Python39\lib\site-packages\telegram\bot.py", line 130, in decorator
    result = func(*args, **kwargs)
  File "C:\Users\Кирилл\AppData\Local\Programs\Python\Python39\lib\site-packages\telegram\bot.py", line 2861, in get_updates
    self._post(
  File "C:\Users\Кирилл\AppData\Local\Programs\Python\Python39\lib\site-packages\telegram\bot.py", line 295, in _post
    return self.request.post(
  File "C:\Users\Кирилл\AppData\Local\Programs\Python\Python39\lib\site-packages\telegram\utils\request.py", line 356, in post
    result = self._request_wrapper(
  File "C:\Users\Кирилл\AppData\Local\Programs\Python\Python39\lib\site-packages\telegram\utils\request.py", line 283, in _request_wrapper
    raise Conflict(message)
telegram.error.Conflict: Conflict: terminated by other getUpdates request; make sure that only one bot instance is running
ERROR:telegram.ext.updater:Error while getting Updates: Conflict: terminated by other getUpdates request; make sure that only one bot instance is running
ERROR:telegram.ext.dispatcher:No error handlers are registered, logging exception.
Traceback (most recent call last):
  File "C:\Users\Кирилл\AppData\Local\Programs\Python\Python39\lib\site-packages\telegram\ext\updater.py", line 646, in _network_loop_retry
    if not action_cb():
  File "C:\Users\Кирилл\AppData\Local\Programs\Python\Python39\lib\site-packages\telegram\ext\updater.py", line 597, in polling_action_cb
    updates = self.bot.get_updates(
  File "C:\Users\Кирилл\AppData\Local\Programs\Python\Python39\lib\site-packages\telegram\ext\extbot.py", line 222, in get_updates
    updates = super().get_updates(
  File "C:\Users\Кирилл\AppData\Local\Programs\Python\Python39\lib\site-packages\telegram\bot.py", line 130, in decorator
    result = func(*args, **kwargs)
  File "C:\Users\Кирилл\AppData\Local\Programs\Python\Python39\lib\site-packages\telegram\bot.py", line 2861, in get_updates
    self._post(
  File "C:\Users\Кирилл\AppData\Local\Programs\Python\Python39\lib\site-packages\telegram\bot.py", line 295, in _post
    return self.request.post(
  File "C:\Users\Кирилл\AppData\Local\Programs\Python\Python39\lib\site-packages\telegram\utils\request.py", line 356, in post
    result = self._request_wrapper(
  File "C:\Users\Кирилл\AppData\Local\Programs\Python\Python39\lib\site-packages\telegram\utils\request.py", line 283, in _request_wrapper
    raise Conflict(message)
telegram.error.Conflict: Conflict: terminated by other getUpdates request; make sure that only one bot instance is running
ERROR:telegram.ext.updater:Error while getting Updates: Conflict: terminated by other getUpdates request; make sure that only one bot instance is running
ERROR:telegram.ext.dispatcher:No error handlers are registered, logging exception.
Traceback (most recent call last):
  File "C:\Users\Кирилл\AppData\Local\Programs\Python\Python39\lib\site-packages\telegram\ext\updater.py", line 646, in _network_loop_retry
    if not action_cb():
  File "C:\Users\Кирилл\AppData\Local\Programs\Python\Python39\lib\site-packages\telegram\ext\updater.py", line 597, in polling_action_cb
    updates = self.bot.get_updates(
  File "C:\Users\Кирилл\AppData\Local\Programs\Python\Python39\lib\site-packages\telegram\ext\extbot.py", line 222, in get_updates
    updates = super().get_updates(
  File "C:\Users\Кирилл\AppData\Local\Programs\Python\Python39\lib\site-packages\telegram\bot.py", line 130, in decorator
    result = func(*args, **kwargs)
  File "C:\Users\Кирилл\AppData\Local\Programs\Python\Python39\lib\site-packages\telegram\bot.py", line 2861, in get_updates
    self._post(
  File "C:\Users\Кирилл\AppData\Local\Programs\Python\Python39\lib\site-packages\telegram\bot.py", line 295, in _post
    return self.request.post(
  File "C:\Users\Кирилл\AppData\Local\Programs\Python\Python39\lib\site-packages\telegram\utils\request.py", line 356, in post
    result = self._request_wrapper(
  File "C:\Users\Кирилл\AppData\Local\Programs\Python\Python39\lib\site-packages\telegram\utils\request.py", line 283, in _request_wrapper
    raise Conflict(message)
telegram.error.Conflict: Conflict: terminated by other getUpdates request; make sure that only one bot instance is running
ERROR:telegram.ext.updater:Error while getting Updates: Conflict: terminated by other getUpdates request; make sure that only one bot instance is running
ERROR:telegram.ext.dispatcher:No error handlers are registered, logging exception.
Traceback (most recent call last):
  File "C:\Users\Кирилл\AppData\Local\Programs\Python\Python39\lib\site-packages\telegram\ext\updater.py", line 646, in _network_loop_retry
    if not action_cb():
  File "C:\Users\Кирилл\AppData\Local\Programs\Python\Python39\lib\site-packages\telegram\ext\updater.py", line 597, in polling_action_cb
    updates = self.bot.get_updates(
  File "C:\Users\Кирилл\AppData\Local\Programs\Python\Python39\lib\site-packages\telegram\ext\extbot.py", line 222, in get_updates
    updates = super().get_updates(
  File "C:\Users\Кирилл\AppData\Local\Programs\Python\Python39\lib\site-packages\telegram\bot.py", line 130, in decorator
    result = func(*args, **kwargs)
  File "C:\Users\Кирилл\AppData\Local\Programs\Python\Python39\lib\site-packages\telegram\bot.py", line 2861, in get_updates
    self._post(
  File "C:\Users\Кирилл\AppData\Local\Programs\Python\Python39\lib\site-packages\telegram\bot.py", line 295, in _post
    return self.request.post(
  File "C:\Users\Кирилл\AppData\Local\Programs\Python\Python39\lib\site-packages\telegram\utils\request.py", line 356, in post
    result = self._request_wrapper(
  File "C:\Users\Кирилл\AppData\Local\Programs\Python\Python39\lib\site-packages\telegram\utils\request.py", line 283, in _request_wrapper
    raise Conflict(message)
telegram.error.Conflict: Conflict: terminated by other getUpdates request; make sure that only one bot instance is running
ERROR:telegram.ext.updater:Error while getting Updates: Conflict: terminated by other getUpdates request; make sure that only one bot instance is running
ERROR:telegram.ext.dispatcher:No error handlers are registered, logging exception.
Traceback (most recent call last):
  File "C:\Users\Кирилл\AppData\Local\Programs\Python\Python39\lib\site-packages\telegram\ext\updater.py", line 646, in _network_loop_retry
    if not action_cb():
  File "C:\Users\Кирилл\AppData\Local\Programs\Python\Python39\lib\site-packages\telegram\ext\updater.py", line 597, in polling_action_cb
    updates = self.bot.get_updates(
  File "C:\Users\Кирилл\AppData\Local\Programs\Python\Python39\lib\site-packages\telegram\ext\extbot.py", line 222, in get_updates
    updates = super().get_updates(
  File "C:\Users\Кирилл\AppData\Local\Programs\Python\Python39\lib\site-packages\telegram\bot.py", line 130, in decorator
    result = func(*args, **kwargs)
  File "C:\Users\Кирилл\AppData\Local\Programs\Python\Python39\lib\site-packages\telegram\bot.py", line 2861, in get_updates
    self._post(
  File "C:\Users\Кирилл\AppData\Local\Programs\Python\Python39\lib\site-packages\telegram\bot.py", line 295, in _post
    return self.request.post(
  File "C:\Users\Кирилл\AppData\Local\Programs\Python\Python39\lib\site-packages\telegram\utils\request.py", line 356, in post
    result = self._request_wrapper(
  File "C:\Users\Кирилл\AppData\Local\Programs\Python\Python39\lib\site-packages\telegram\utils\request.py", line 283, in _request_wrapper
    raise Conflict(message)
telegram.error.Conflict: Conflict: terminated by other getUpdates request; make sure that only one bot instance is running
ERROR:telegram.ext.updater:Error while getting Updates: Conflict: terminated by other getUpdates request; make sure that only one bot instance is running
ERROR:telegram.ext.dispatcher:No error handlers are registered, logging exception.
Traceback (most recent call last):
  File "C:\Users\Кирилл\AppData\Local\Programs\Python\Python39\lib\site-packages\telegram\ext\updater.py", line 646, in _network_loop_retry
    if not action_cb():
  File "C:\Users\Кирилл\AppData\Local\Programs\Python\Python39\lib\site-packages\telegram\ext\updater.py", line 597, in polling_action_cb
    updates = self.bot.get_updates(
  File "C:\Users\Кирилл\AppData\Local\Programs\Python\Python39\lib\site-packages\telegram\ext\extbot.py", line 222, in get_updates
    updates = super().get_updates(
  File "C:\Users\Кирилл\AppData\Local\Programs\Python\Python39\lib\site-packages\telegram\bot.py", line 130, in decorator
    result = func(*args, **kwargs)
  File "C:\Users\Кирилл\AppData\Local\Programs\Python\Python39\lib\site-packages\telegram\bot.py", line 2861, in get_updates
    self._post(
  File "C:\Users\Кирилл\AppData\Local\Programs\Python\Python39\lib\site-packages\telegram\bot.py", line 295, in _post
    return self.request.post(
  File "C:\Users\Кирилл\AppData\Local\Programs\Python\Python39\lib\site-packages\telegram\utils\request.py", line 356, in post
    result = self._request_wrapper(
  File "C:\Users\Кирилл\AppData\Local\Programs\Python\Python39\lib\site-packages\telegram\utils\request.py", line 283, in _request_wrapper
    raise Conflict(message)
telegram.error.Conflict: Conflict: terminated by other getUpdates request; make sure that only one bot instance is running
ERROR:telegram.ext.updater:Error while getting Updates: Conflict: terminated by other getUpdates request; make sure that only one bot instance is running
ERROR:telegram.ext.dispatcher:No error handlers are registered, logging exception.
Traceback (most recent call last):
  File "C:\Users\Кирилл\AppData\Local\Programs\Python\Python39\lib\site-packages\telegram\ext\updater.py", line 646, in _network_loop_retry
    if not action_cb():
  File "C:\Users\Кирилл\AppData\Local\Programs\Python\Python39\lib\site-packages\telegram\ext\updater.py", line 597, in polling_action_cb
    updates = self.bot.get_updates(
  File "C:\Users\Кирилл\AppData\Local\Programs\Python\Python39\lib\site-packages\telegram\ext\extbot.py", line 222, in get_updates
    updates = super().get_updates(
  File "C:\Users\Кирилл\AppData\Local\Programs\Python\Python39\lib\site-packages\telegram\bot.py", line 130, in decorator
    result = func(*args, **kwargs)
  File "C:\Users\Кирилл\AppData\Local\Programs\Python\Python39\lib\site-packages\telegram\bot.py", line 2861, in get_updates
    self._post(
  File "C:\Users\Кирилл\AppData\Local\Programs\Python\Python39\lib\site-packages\telegram\bot.py", line 295, in _post
    return self.request.post(
  File "C:\Users\Кирилл\AppData\Local\Programs\Python\Python39\lib\site-packages\telegram\utils\request.py", line 356, in post
    result = self._request_wrapper(
  File "C:\Users\Кирилл\AppData\Local\Programs\Python\Python39\lib\site-packages\telegram\utils\request.py", line 283, in _request_wrapper
    raise Conflict(message)
telegram.error.Conflict: Conflict: terminated by other getUpdates request; make sure that only one bot instance is running
ERROR:telegram.ext.updater:Error while getting Updates: Conflict: terminated by other getUpdates request; make sure that only one bot instance is running
ERROR:telegram.ext.dispatcher:No error handlers are registered, logging exception.
Traceback (most recent call last):
  File "C:\Users\Кирилл\AppData\Local\Programs\Python\Python39\lib\site-packages\telegram\ext\updater.py", line 646, in _network_loop_retry
    if not action_cb():
  File "C:\Users\Кирилл\AppData\Local\Programs\Python\Python39\lib\site-packages\telegram\ext\updater.py", line 597, in polling_action_cb
    updates = self.bot.get_updates(
  File "C:\Users\Кирилл\AppData\Local\Programs\Python\Python39\lib\site-packages\telegram\ext\extbot.py", line 222, in get_updates
    updates = super().get_updates(
  File "C:\Users\Кирилл\AppData\Local\Programs\Python\Python39\lib\site-packages\telegram\bot.py", line 130, in decorator
    result = func(*args, **kwargs)
  File "C:\Users\Кирилл\AppData\Local\Programs\Python\Python39\lib\site-packages\telegram\bot.py", line 2861, in get_updates
    self._post(
  File "C:\Users\Кирилл\AppData\Local\Programs\Python\Python39\lib\site-packages\telegram\bot.py", line 295, in _post
    return self.request.post(
  File "C:\Users\Кирилл\AppData\Local\Programs\Python\Python39\lib\site-packages\telegram\utils\request.py", line 356, in post
    result = self._request_wrapper(
  File "C:\Users\Кирилл\AppData\Local\Programs\Python\Python39\lib\site-packages\telegram\utils\request.py", line 283, in _request_wrapper
    raise Conflict(message)
telegram.error.Conflict: Conflict: terminated by other getUpdates request; make sure that only one bot instance is running
ERROR:telegram.ext.updater:Error while getting Updates: Conflict: terminated by other getUpdates request; make sure that only one bot instance is running
ERROR:telegram.ext.dispatcher:No error handlers are registered, logging exception.
Traceback (most recent call last):
  File "C:\Users\Кирилл\AppData\Local\Programs\Python\Python39\lib\site-packages\telegram\ext\updater.py", line 646, in _network_loop_retry
    if not action_cb():
  File "C:\Users\Кирилл\AppData\Local\Programs\Python\Python39\lib\site-packages\telegram\ext\updater.py", line 597, in polling_action_cb
    updates = self.bot.get_updates(
  File "C:\Users\Кирилл\AppData\Local\Programs\Python\Python39\lib\site-packages\telegram\ext\extbot.py", line 222, in get_updates
    updates = super().get_updates(
  File "C:\Users\Кирилл\AppData\Local\Programs\Python\Python39\lib\site-packages\telegram\bot.py", line 130, in decorator
    result = func(*args, **kwargs)
  File "C:\Users\Кирилл\AppData\Local\Programs\Python\Python39\lib\site-packages\telegram\bot.py", line 2861, in get_updates
    self._post(
  File "C:\Users\Кирилл\AppData\Local\Programs\Python\Python39\lib\site-packages\telegram\bot.py", line 295, in _post
    return self.request.post(
  File "C:\Users\Кирилл\AppData\Local\Programs\Python\Python39\lib\site-packages\telegram\utils\request.py", line 356, in post
    result = self._request_wrapper(
  File "C:\Users\Кирилл\AppData\Local\Programs\Python\Python39\lib\site-packages\telegram\utils\request.py", line 283, in _request_wrapper
    raise Conflict(message)
telegram.error.Conflict: Conflict: terminated by other getUpdates request; make sure that only one bot instance is running
INFO:telegram.ext.updater:Received signal 2 (SIGINT), stopping...
INFO:apscheduler.scheduler:Scheduler has been shut down
